Workbook

Sheet 01 غلاف المشروع
B2: مشروع تحليل بيانات مستشفى شامل
B3: Hospital Operations & Patient Analytics — من البيانات الخام إلى لوحة تحكم تفاعلية
B5: هذا المشروع عبارة عن تحليل بيانات كامل لعمليات مستشفى عام افتراضي خلال عام 2024، يغطي 2,100 حالة دخول بعد التنظيف عبر 8 أقسام طبية. يوثّق الملف رحلة البيانات كاملة: من البيانات الخام بمشاكلها الحقيقية (قيم مفقودة، تكرار، تنسيقات غير متسقة، قيم شاذة)، مروراً بخطوات التنظيف الموثقة رقمياً، وصولاً إلى جداول تحليلية (بديل الجدول المحوري) ورسوم بيانية ولوحة تحكم تفاعلية بأهم مؤشرات الأداء (KPIs)، وانتهاءً برؤى وتوصيات عملية قابلة للتنفيذ.
B10: لمحة سريعة عن البيانات
B11: عدد السجلات (خام) | C11: 2142
B12: عدد السجلات (نظيفة) | C12: 2100
B13: الفترة الزمنية | C13: 2024 (12 شهراً)
B14: عدد الأقسام الطبية | C14: 8
B15: عدد الأعمدة/المتغيرات | C15: 15
B18: فهرس الملف
B19: اسم الشيت | C19: المحتوى
B20: 01 غلاف المشروع | C20: نظرة عامة على المشروع ومنهجيته
B21: 02 قاموس البيانات | C21: وصف كل عمود ونوعه ومصدره
B22: 03 سجل التنظيف | C22: خطوات تنظيف البيانات موثقة رقمياً قبل/بعد
B23: 04 البيانات الخام | C23: عينة من البيانات الأصلية بمشاكلها قبل التنظيف
B24: 05 البيانات النظيفة | C24: قاعدة البيانات الكاملة النظيفة (2,100 سجل) مع أعمدة محسوبة
B25: 06 الجداول التحليلية | C25: جداول تحليلية شاملة (بديل الجدول المحوري) لكل الأبعاد
B26: 07 لوحة التحكم | C26: داشبورد تفاعلي بأهم المؤشرات مع فلتر حسب القسم
B27: 08 رسوم بيانية إضافية | C27: رسوم بيانية تفصيلية تكميلية
B28: 09 الرؤى والتوصيات | C28: الاستنتاجات الرئيسية والتوصيات العملية
B31: ملاحظة: جميع البيانات في هذا الملف اصطناعية (Synthetic) تم توليدها لأغراض تعليمية/بورتفوليو، وتحاكي أنماطاً واقعية لعمليات المستشفيات ولا تعود لأي مستشفى أو مريض حقيقي.

Sheet 02 قاموس البيانات
A1: قاموس البيانات (Data Dictionary)
A3: # | B3: اسم العمود | C3: نوع البيانات | D3: الوصف | E3: المصدر / طريقة الاشتقاق
A4: 1 | B4: المعرف | C4: نصي | D4: معرّف فريد لكل حالة دخول (زيارة) للمريض، بصيغة Pxxxxx | E4: مولّد آلياً
A5: 2 | B5: تاريخ_الدخول | C5: تاريخ | D5: تاريخ دخول المريض إلى المستشفى | E5: نظام القبول والتسجيل
A6: 3 | B6: تاريخ_الخروج | C6: تاريخ | D6: تاريخ خروج المريض من المستشفى | E6: نظام القبول والتسجيل
A7: 4 | B7: العمر | C7: رقمي | D7: عمر المريض بالسنوات وقت الدخول | E7: ملف المريض
A8: 5 | B8: الجنس | C8: نصي (فئوي) | D8: ذكر / أنثى | E8: ملف المريض
A9: 6 | B9: القسم | C9: نصي (فئوي) | D9: القسم الطبي المسؤول عن الحالة (8 أقسام) | E9: نظام إدارة الأسرّة
A10: 7 | B10: التشخيص | C10: نصي (فئوي) | D10: التشخيص الأساسي المرتبط بالحالة | E10: الملف الطبي
A11: 8 | B11: الطبيب_المعالج | C11: نصي (فئوي) | D11: اسم الطبيب المسؤول عن متابعة الحالة | E11: نظام الموارد البشرية
A12: 9 | B12: نوع_الدخول | C12: نصي (فئوي) | D12: طارئة / اختيارية / تحويل من مستشفى آخر | E12: نظام القبول
A13: 10 | B13: نوع_الغرفة | C13: نصي (فئوي) | D13: عادية / خاصة / عناية مركزة | E13: نظام إدارة الأسرّة
A14: 11 | B14: نوع_التأمين | C14: نصي (فئوي) | D14: جهة تغطية تكلفة العلاج | E14: قسم الفوترة
A15: 12 | B15: التكلفة_الإجمالية | C15: رقمي (عملة) | D15: إجمالي تكلفة الحالة بالريال السعودي (SAR) | E15: قسم الفوترة
... A18: 15 | B18: حالة_الخروج | C18: نصي (فئوي) | D18: خرج بحالة مستقرة / تحويل لمستشفى آخر / خروج بطلب ذاتي / وفاة | E18: الملف الطبي
A19: — أعمدة محسوبة في شيت البيانات النظيفة —
A20: 16 | B20: مدة_الإقامة_أيام | C20: رقمي (محسوب) | D20: الفرق: تاريخ_الخروج ناقص تاريخ_الدخول (بالأيام) | E20: صيغة
A21: 17 | B21: الشهر | C21: نصي (محسوب) | D21: اسم شهر الدخول مستخرج من تاريخ_الدخول | E21: صيغة
A22: 18 | B22: الربع | C22: نصي (محسوب) | D22: الربع السنوي لتاريخ الدخول (١-٤) | E22: صيغة
A23: 19 | B23: الفئة_العمرية | C23: نصي (محسوب) | D23: تصنيف العمر إلى 5 فئات عمرية | E23: صيغة
A24: 20 | B24: تكلفة_اليوم_الواحد | C24: رقمي (محسوب) | D24: ناتج قسمة التكلفة_الإجمالية على مدة_الإقامة_أيام | E24: صيغة

Sheet 03 سجل التنظيف
A1: سجل تنظيف البيانات (Data Cleaning Log)
A2: توثيق كامل لكل خطوة تنظيف تمت على البيانات الخام، مع الأرقام الفعلية قبل وبعد كل معالجة
A4: # | B4: الخطوة | C4: التفاصيل
A5: 1 | B5: عدد السجلات الأولي (خام) | C5: 2142 سجل قبل أي تنظيف
A6: 2 | B6: إزالة السجلات المكررة | C6: تم حذف 42 سجل مكرر بالاعتماد على عمود المعرف (المعرّف الفريد للمريض/الزيارة)
A7: 3 | B7: توحيد أسماء الأقسام | C7: تم توحيد الأشكال النصية المختلفة لاسم القسم (مسافات زائدة، اختصارات، أخطاء إملائية) — من 15 صيغة نصية مختلفة إلى 8 قسم موحّد
A8: 4 | B8: توحيد عمود الجنس | C8: توحيد القيم الإنجليزية/العربية والمسافات الزائدة إلى قيمتين موحّدتين: ذكر / أنثى
A9: 5 | B9: تصحيح التواريخ المعكوسة | C9: تم اكتشاف وتصحيح 8 سجل كان فيه تاريخ الخروج أسبق من تاريخ الدخول (خطأ إدخال) بمبادلة القيمتين
A10: 6 | B10: معالجة قيم العمر الشاذة والمفقودة | C10: تم تحويل 15 قيمة غير منطقية (سالبة أو أكبر من 110) إلى مفقودة، ثم تعويض إجمالي 56 قيمة عمر مفقودة بوسيط العمر لنفس القسم الطبي (Median Imputation by Department)
A11: 7 | B11: معالجة التكلفة غير المنطقية | C11: تم استبدال 10 قيمة تكلفة سالبة أو صفرية (خطأ إدخال) بوسيط التكلفة لنفس القسم ونوع الغرفة
A12: 8 | B12: معالجة تقييم رضا المريض | C12: تم تصحيح 6 قيمة تقييم خارج النطاق المسموح (1-5)، وتعويض 111 قيمة مفقودة بوسيط القسم
A13: 9 | B13: تعويض نوع التأمين المفقود | C13: تم تعويض 62 قيمة مفقودة بالقيمة الأكثر شيوعاً في البيانات: "تأمين حكومي" (Mode Imputation)
A14: 10 | B14: معالجة الطبيب المعالج المفقود | C14: تم تصنيف 32 سجل لم يحتو على اسم الطبيب المعالج ضمن فئة "غير محدد" بدلاً من حذفها أو تخمين طبيب غير صحيح
A15: 11 | B15: تعويض حالة الخروج المفقودة | C15: تم تعويض 39 قيمة مفقودة بالحالة الأكثر شيوعاً ضمن نفس القسم الطبي
A16: 12 | B16: التحقق النهائي من اتساق التواريخ | C16: بعد التصحيح: عدد السجلات التي لا تزال فيها مدة إقامة سالبة = 0 (تم التأكد أنها صفر)
A17: 13 | B17: عدد السجلات النهائي (بعد التنظيف) | C17: 2100 سجل نظيف وجاهز للتحليل (من أصل 2142 سجل خام)
A20: ملخص الأثر الإجمالي للتنظيف
A21: المقياس | B21: قبل التنظيف | C21: بعد التنظيف
A22: عدد السجلات | B22: 2142 | C22: 2100
A23: عدد السجلات المكررة | B23: 42 | C23: 0
A24: القيم المفقودة الإجمالية | B24: 287 | C24: 0

Sheet 04 البيانات الخام
A1: البيانات الخام قبل التنظيف (عينة كاملة كما وردت من الأنظمة المصدرية)
A2: لاحظ: قيم مفقودة، تكرار في المعرف، عدم اتساق نصي (مسافات/لغة)، قيم عمر وتكلفة غير منطقية، وتواريخ معكوسة — تم رصدها ومعالجتها في شيت (03 سجل التنظيف)
A4: المعرف | B4: تاريخ_الدخول | C4: تاريخ_الخروج | D4: العمر | E4: الجنس | F4: القسم | G4: التشخيص | H4: الطبيب_المعالج | I4: نوع_الدخول | J4: نوع_الغرفة | K4: نوع_التأمين | L4: التكلفة_الإجمالية | M4: تقييم_رضا_المريض | N4: إعادة_دخول_خلال_30_يوم | O4: حالة_الخروج
A5: P10923 | B5: 45345 | C5: 45347 | D5: 43 | E5: أنثى | F5: الجراحة العامة | G5: التهاب الزائدة الدودية | H5: د. يوسف الدوسري | I5: طارئة | J5: خاصة | K5: تأمين حكومي | L5: 7827.45 | M5: 4 | N5: لا | O5: خرج بحالة مستقرة
A6: P11513 | B6: 45413 | C6: 45414 | D6: 26 | E6: أنثى | F6: النساء والولادة | G6: متابعة حمل عالي الخطورة | H6: د. وفاء الزهراني | I6: اختيارية | J6: خاصة | K6: تأمين حكومي | L6: 2740.6 | M6: 5 | N6: لا | O6: خرج بحالة مستقرة
A7: P11593 | B7: 45298 | C7: 45301 | D7: 6 | E7: ذكر | F7: الأطفال | G7: التهاب الشعب الهوائية | H7: د. سلطان الجهني | I7: تحويل من مستشفى آخر | J7: عادية | K7: تأمين خاص | L7: 2677.91 | M7: 4 | N7: لا | O7: خرج بحالة مستقرة
A8: P11648 | B8: 45649 | C8: 45653 | D8: 20 | E8: ذكر | F8: الباطنه | G8: فشل كلوي مزمن | H8: د. خالد الزهراني | I8: طارئة | J8: عادية | K8: تأمين خاص | L8: 4513.64 | M8: 4 | N8: لا | O8: خرج بحالة مستقرة
A9: P10651 | B9: 45530 | C9: 45534 | D9: 52 | E9: أنثى | F9: الجراحة العامة | G9: التهاب الزائدة الدودية | H9: د. يوسف الدوسري | I9: اختيارية | J9: خاصة | K9: تأمين حكومي | L9: 16134.25 | M9: 5 | N9: لا | O9: خرج بحالة مستقرة
A10: P10922 | B10: 45455 | C10: 45458 | D10: 60 | E10: أنثى | F10: الجراحة العامة | G10: استئصال المرارة | H10: د. يوسف الدوسري | I10: طارئة | J10: خاصة | K10: تأمين حكومي | L10: 13156.21 | M10: 5 | N10: لا | O10: خرج بحالة مستقرة
A11: P10328 | B11: 45343 | C11: 45346 | D11: 12 | E11: ذكر | F11: الباطنة | G11: سكري غير منضبط | H11: د. عبدالله الشمري | I11: طارئة | J11: خاصة | K11: تأمين خاص | L11: 6467.63 | M11: 4 | N11: لا | O11: خرج بحالة مستقرة
A12: P10856 | B12: 45381 | C12: 45386 | D12: 45 | E12: أنثى | F12: العظام | G12: إصابة رباط | H12: د. تركي العنزي | I12: تحويل من مستشفى آخر | J12: عناية مركزة | K12: تأمين خاص | L12: 46395.01 | M12: 5 | N12: لا | O12: خرج بحالة مستقرة
A13: P10562 | B13: 45472 | C13: 45475 | D13: 9 | E13: أنثى | F13: العظام | G13: كسر عظمي | H13: د. تركي العنزي | I13: طارئة | J13: عادية | K13: تأمين خاص | L13: 6798.59 | M13: 4 | N13: لا | O13: خرج بحالة مستقرة
A14: P11484 | B14: 45443 | C14: 45449 | D14: 62 | E14: Male | F14: أمراض القلب | G14: احتشاء عضلة القلب | H14: د. هند الحارثي | I14: اختيارية | J14: عادية | K14: ضمان اجتماعي | L14: 14266.05 | M14: 5 | N14: لا | O14: خرج بحالة مستقرة
A15: P11700 | B15: 45389 | C15: 45390 | D15: 18 | E15: أنثى | F15: النساء والولادة | G15: متابعة حمل عالي الخطورة | H15: د. غادة العمري | I15: طارئة | J15: عناية مركزة | K15: تأمين خاص | L15: 5284.81 | M15: 3 | N15: لا | O15: خرج بحالة مستقرة
A16: P11797 | B16: 45359 | C16: 45364 | D16: 45 | E16: ذكر | F16: أمراض القلب | G16: عدم انتظام ضربات القلب | H16: د. هند الحارثي | I16: تحويل من مستشفى آخر | J16: خاصة | K16: ضمان اجتماعي | L16: 20613.92 | M16: 3 | N16: لا | O16: خرج بحالة مستقرة
... A19: P10755 | B19: 45452 | C19: 45454 | D19: 67 | E19: أنثى | F19: أمراض القلب | G19: احتشاء عضلة القلب | H19: د. هند الحارثي | I19: تحويل من مستشفى آخر | J19: عادية | K19: تأمين حكومي | L19: 4462.32 | M19: 3 | N19: لا | O19: خرج بحالة مستقرة
A20: P12095 | B20: 45576 | C20: 45585 | D20: 39 | E20: أنثى | F20: العظام | G20: استبدال مفصل الركبة | H20: د. لينا السبيعي | I20: طارئة | J20: عادية | L20: 20420.2 | M20: 4 | N20: لا | O20: خرج بحالة مستقرة
A21: P11795 | B21: 45365 | C21: 45370 | D21: 23 | E21: أنثى | F21: العظام | G21: إصابة رباط | H21: د. لينا السبيعي | I21: اختيارية | J21: عناية مركزة | K21: تأمين حكومي | L21: 52813.28 | M21: 3 | N21: لا | O21: خرج بحالة مستقرة
A22: P11933 | B22: 45640 | C22: 45650 | D22: 60 | E22: ذكر | F22: الجراحة العامة | G22: التهاب الزائدة الدودية | H22: د. يوسف الدوسري | I22: تحويل من مستشفى آخر | J22: خاصة | K22: تأمين خاص | L22: 41917 | M22: 3 | N22: لا | O22: خرج بحالة مستقرة
A23: P10789 | B23: 45296 | C23: 45298 | D23: 50 | E23: ذكر | F23: الطوارئ | G23: إصابة حادة | H23: د. فهد المطيري | I23: اختيارية | J23: خاصة | K23: ضمان اجتماعي | L23: 3595.62 | M23: 3 | N23: لا | O23: تحويل لمستشفى آخر
A24: P10140 | B24: 45651 | C24: 45657 | D24: 45 | E24: ذكر | F24: العظام | G24: كسر عظمي | H24: د. تركي العنزي | I24: طارئة | J24: عادية | K24: تأمين حكومي | L24: 12715.75 | M24: 5 | N24: لا | O24: خرج بحالة مستقرة
A25: P10415 | B25: 45540 | C25: 45552 | D25: 66 | E25: ذكر | F25: العظام | G25: إصابة رباط | H25: د. تركي العنزي | I25: اختيارية | J25: عادية | K25: بدون تأمين (ذاتي) | L25: 35935.34 | M25: 4 | N25: نعم | O25: خرج بحالة مستقرة
A26: P12079 | B26: 45338 | C26: 45341 | D26: 46 | E26: ذكر | F26: الباطنة | G26: التهاب رئوي | H26: د. منى القحطاني | I26: اختيارية | J26: عادية | K26: تأمين خاص | L26: 2836.96 | M26: 4 | N26: لا | O26: خرج بحالة مستقرة
A27: P10611 | B27: 45461 | C27: 45464 | D27: 43 | E27: أنثى | F27: العظام | G27: إصابة رباط | H27: د. لينا السبيعي | I27: اختيارية | J27: عادية | K27: تأمين حكومي | L27: 8193.12 | M27: 4 | N27: لا | O27: خرج بحالة مستقرة
A28: P10717 | B28: 45472 | C28: 45473 | D28: 23 | E28: Female | F28: الطوارئ | G28: حروق | H28: د. فهد المطيري | I28: طارئة | J28: عادية | K28: تأمين حكومي | L28: 893.56 | M28: 3 | N28: لا | O28: خرج بحالة مستقرة
A29: P10885 | B29: 45560 | C29: 45562 | D29: 24 | E29: أنثى | F29: النساء والولادة | G29: متابعة حمل عالي الخطورة | H29: د. وفاء الزهراني | I29: طارئة | J29: عناية مركزة | K29: ضمان اجتماعي | L29: 9026.63 | M29: 4 | N29: لا | O29: خرج بحالة مستقرة
A30: P11808 | B30: 45324 | C30: 45325 | D30: 9 | E30: ذكر | F30: الأطفال | G30: جفاف حاد | H30: د. سلطان الجهني | I30: طارئة | J30: عادية | K30: ضمان اجتماعي | L30: 845.42 | M30: 4 | N30: لا | O30: خرج بحالة مستقرة
A31: P11346 | B31: 45605 | C31: 45606 | D31: 3 | E31: أنثى | F31: الأطفال | G31: التهاب الشعب الهوائية | H31: د. أمل باقادر | I31: طارئة | J31: عادية | K31: تأمين حكومي | L31: 582.59 | M31: 3 | N31: لا | O31: خرج بحالة مستقرة
A32: P12071 | B32: 45528 | C32: 45530 | D32: 35 | E32: أنثى | F32: النساء والولادة | G32: ولادة طبيعية | H32: د. غادة العمري | I32: اختيارية | J32: عناية مركزة | K32: تأمين خاص | L32: 8534.42 | M32: 4 | N32: لا | O32: خرج بحالة مستقرة
... A42: P11437 | B42: 45530 | C42: 45535 | D42: 48 | E42: أنثى | F42: أمراض القلب | G42: قصور القلب | H42: د. ماجد الشهري | I42: طارئة | J42: عناية مركزة | K42: تأمين حكومي | L42: 44034.66 | M42: 5 | N42: لا | O42: خرج بحالة مستقرة
A43: P11927 | B43: 45337 | C43: 45338 | D43: 7 | E43: ذكر | F43: الطوارئ | G43: تسمم غذائي | H43: د. سارة الحربي | I43: طارئة | J43: عناية مركزة | L43: 3428.61 | M43: 4 | N43: لا | O43: خروج بطلب ذاتي
A44: P11645 | B44: 45399 | C44: 45400 | D44: 40 | E44: ذكر | F44: الطوارئ | G44: إصابة حادة | H44: د. نورة العتيبي | I44: طارئة | J44: عادية | K44: تأمين حكومي | L44: 861.64 | M44: 3 | N44: لا | O44: خرج بحالة مستقرة
A45: P10986 | B45: 45517 | C45: 45527 | D45: 55 | E45: أنثى | F45: أمراض القلب | G45: عدم انتظام ضربات القلب | H45: د. ماجد الشهري | I45: طارئة | J45: خاصة | K45: تأمين خاص | L45: -500 | N45: لا | O45: خرج بحالة مستقرة
A46: P11195 | B46: 45523 | C46: 45528 | D46: 64 | E46: أنثى | F46: أمراض القلب | G46: احتشاء عضلة القلب | H46: د. هند الحارثي | I46: تحويل من مستشفى آخر | J46: عادية | K46: بدون تأمين (ذاتي) | L46: 12253.85 | M46: 2 | N46: لا | O46: خرج بحالة مستقرة
A47: P11683 | B47: 45583 | C47: 45588 | D47: 57 | E47: ذكر | F47: أمراض القلب | G47: قصور القلب | H47: د. ماجد الشهري | I47: اختيارية | J47: عادية | K47: ضمان اجتماعي | L47: 11210.85 | M47: 4 | N47: لا | O47: خروج بطلب ذاتي
A48: P12011 | B48: 45435 | C48: 45440 | D48: 24 | E48: أنثى | F48: العظام | G48: استبدال مفصل الركبة | H48: د. تركي العنزي | I48: طارئة | J48: عادية | K48: تأمين خاص | L48: 12358.31 | M48: 4 | N48: نعم | O48: خرج بحالة مستقرة
A49: P11457 | B49: 45458 | C49: 45459 | D49: 56 | E49: أنثى | F49: الطوارئ | G49: كسر طارئ | H49: د. نورة العتيبي | I49: طارئة | J49: عادية | L49: 858.46 | M49: 4 | N49: لا | O49: خرج بحالة مستقرة
A50: P11085 | B50: 45599 | C50: 45604 | D50: 63 | E50: ذكر | F50: العظام | G50: إصابة رباط | H50: د. تركي العنزي | I50: تحويل من مستشفى آخر | J50: خاصة | K50: تأمين خاص | L50: 22038.64 | M50: 3 | N50: لا | O50: خرج بحالة مستقرة
A51: P11419 | B51: 45466 | C51: 45468 | D51: 7 | E51: Female | F51: الأطفال | G51: جفاف حاد | H51: د. أمل باقادر | I51: طارئة | J51: عادية | K51: تأمين خاص | L51: 1626.47 | M51: 4 | N51: لا | O51: خرج بحالة مستقرة
A52: P11883 | B52: 45601 | C52: 45610 | D52: 35 | E52: ذكر | F52: الأورام | G52: متابعة ورم | H52: د. دانة المالكي | I52: طارئة | J52: عادية | K52: تأمين حكومي | L52: 25981.99 | M52: 4 | N52: لا | O52: خرج بحالة مستقرة
...

Sheet 05 البيانات النظيفة
A1: قاعدة البيانات النظيفة (المصدر الأساسي لجميع الجداول والمخططات) — 2,100 سجل
A2: المعرف | B2: تاريخ_الدخول | C2: تاريخ_الخروج | D2: العمر | E2: الجنس | F2: القسم | G2: التشخيص | H2: الطبيب_المعالج | I2: نوع_الدخول | J2: نوع_الغرفة | K2: نوع_التأمين | L2: التكلفة_الإجمالية | M2: تقييم_رضا_المريض | N2: إعادة_دخول_خلال_30_يوم | O2: حالة_الخروج | P2: مدة_الإقامة_أيام | Q2: الشهر | R2: الربع | S2: الفئة_العمرية | T2: تكلفة_اليوم_الواحد
A3: P11995 | B3: 45292 | C3: 45293 | D3: 9 | E3: أنثى | F3: الأطفال | G3: جفاف حاد | H3: د. أمل باقادر | I3: طارئة | J3: عناية مركزة | K3: تأمين حكومي | L3: 2923.08 | M3: 3 | N3: لا | O3: خرج بحالة مستقرة | P3: =C3-B3 -> 1 | Q3: =CHOOSE(MONTH(B3),"يناير","فبراير","مارس","أبريل","مايو","يونيو","يوليو","أغسطس","سبتمبر","أكتوبر","نوفمبر","ديسمبر") -> يناير | R3: ="الربع "&ROUNDUP(MONTH(B3)/3,0) -> الربع 1 | S3: =IF(D3<=12,"أطفال (0-12)",IF(D3<=24,"شباب (13-24)",IF(D3<=44,"بالغون (25-44)",IF(D3<=64,"متوسطو العمر (45-64)","كبار السن (+65)")))) -> أطفال (0-12) | T3: =IFERROR(L3/P3,0) -> 2923.08
A4: P11481 | B4: 45292 | C4: 45295 | D4: 10 | E4: أنثى | F4: الأطفال | G4: التهاب الشعب الهوائية | H4: د. سلطان الجهني | I4: تحويل من مستشفى آخر | J4: عادية | K4: تأمين حكومي | L4: 2663.31 | M4: 3 | N4: نعم | O4: خرج بحالة مستقرة | P4: =C4-B4 -> 3 | Q4: =CHOOSE(MONTH(B4),"يناير","فبراير","مارس","أبريل","مايو","يونيو","يوليو","أغسطس","سبتمبر","أكتوبر","نوفمبر","ديسمبر") -> يناير | R4: ="الربع "&ROUNDUP(MONTH(B4)/3,0) -> الربع 1 | S4: =IF(D4<=12,"أطفال (0-12)",IF(D4<=24,"شباب (13-24)",IF(D4<=44,"بالغون (25-44)",IF(D4<=64,"متوسطو العمر (45-64)","كبار السن (+65)")))) -> أطفال (0-12) | T4: =IFERROR(L4/P4,0) -> 887.77
A5: P11948 | B5: 45292 | C5: 45295 | D5: 28 | E5: ذكر | F5: الباطنة | G5: ضغط الدم المرتفع | H5: د. خالد الزهراني | I5: اختيارية | J5: خاصة | K5: تأمين خاص | L5: 5699.39 | M5: 5 | N5: لا | O5: خرج بحالة مستقرة | P5: =C5-B5 -> 3 | Q5: =CHOOSE(MONTH(B5),"يناير","فبراير","مارس","أبريل","مايو","يونيو","يوليو","أغسطس","سبتمبر","أكتوبر","نوفمبر","ديسمبر") -> يناير | R5: ="الربع "&ROUNDUP(MONTH(B5)/3,0) -> الربع 1 | S5: =IF(D5<=12,"أطفال (0-12)",IF(D5<=24,"شباب (13-24)",IF(D5<=44,"بالغون (25-44)",IF(D5<=64,"متوسطو العمر (45-64)","كبار السن (+65)")))) -> بالغون (25-44) | T5: =IFERROR(L5/P5,0) -> 1899.7967
A6: P11408 | B6: 45292 | C6: 45294 | D6: 12 | E6: أنثى | F6: الأطفال | G6: حمى فيروسية | H6: د. أمل باقادر | I6: طارئة | J6: عادية | K6: تأمين حكومي | L6: 1749.01 | M6: 4 | N6: لا | O6: خرج بحالة مستقرة | P6: =C6-B6 -> 2 | Q6: =CHOOSE(MONTH(B6),"يناير","فبراير","مارس","أبريل","مايو","يونيو","يوليو","أغسطس","سبتمبر","أكتوبر","نوفمبر","ديسمبر") -> يناير | R6: ="الربع "&ROUNDUP(MONTH(B6)/3,0) -> الربع 1 | S6: =IF(D6<=12,"أطفال (0-12)",IF(D6<=24,"شباب (13-24)",IF(D6<=44,"بالغون (25-44)",IF(D6<=64,"متوسطو العمر (45-64)","كبار السن (+65)")))) -> أطفال (0-12) | T6: =IFERROR(L6/P6,0) -> 874.505
A7: P11487 | B7: 45292 | C7: 45295 | D7: 23 | E7: أنثى | F7: النساء والولادة | G7: ولادة طبيعية | H7: د. غادة العمري | I7: تحويل من مستشفى آخر | J7: عادية | K7: تأمين حكومي | L7: 4939.21 | M7: 5 | N7: لا | O7: خرج بحالة مستقرة | P7: =C7-B7 -> 3 | Q7: =CHOOSE(MONTH(B7),"يناير","فبراير","مارس","أبريل","مايو","يونيو","يوليو","أغسطس","سبتمبر","أكتوبر","نوفمبر","ديسمبر") -> يناير | R7: ="الربع "&ROUNDUP(MONTH(B7)/3,0) -> الربع 1 | S7: =IF(D7<=12,"أطفال (0-12)",IF(D7<=24,"شباب (13-24)",IF(D7<=44,"بالغون (25-44)",IF(D7<=64,"متوسطو العمر (45-64)","كبار السن (+65)")))) -> شباب (13-24) | T7: =IFERROR(L7/P7,0) -> 1646.4033
A8: P10772 | B8: 45293 | C8: 45300 | D8: 50 | E8: ذكر | F8: الأورام | G8: جراحة إزالة ورم | H8: د. فيصل الرشيدي | I8: اختيارية | J8: عادية | K8: تأمين حكومي | L8: 26582.81 | M8: 3 | N8: نعم | O8: خرج بحالة مستقرة | P8: =C8-B8 -> 7 | Q8: =CHOOSE(MONTH(B8),"يناير","فبراير","مارس","أبريل","مايو","يونيو","يوليو","أغسطس","سبتمبر","أكتوبر","نوفمبر","ديسمبر") -> يناير | R8: ="الربع "&ROUNDUP(MONTH(B8)/3,0) -> الربع 1 | S8: =IF(D8<=12,"أطفال (0-12)",IF(D8<=24,"شباب (13-24)",IF(D8<=44,"بالغون (25-44)",IF(D8<=64,"متوسطو العمر (45-64)","كبار السن (+65)")))) -> متوسطو العمر (45-64) | T8: =IFERROR(L8/P8,0) -> 3797.5443
A9: P11912 | B9: 45293 | C9: 45295 | D9: 46 | E9: أنثى | F9: الجراحة العامة | G9: التهاب الزائدة الدودية | H9: د. ريم الغامدي | I9: طارئة | J9: عادية | K9: تأمين حكومي | L9: 4652.7 | M9: 3 | N9: لا | O9: خرج بحالة مستقرة | P9: =C9-B9 -> 2 | Q9: =CHOOSE(MONTH(B9),"يناير","فبراير","مارس","أبريل","مايو","يونيو","يوليو","أغسطس","سبتمبر","أكتوبر","نوفمبر","ديسمبر") -> يناير | R9: ="الربع "&ROUNDUP(MONTH(B9)/3,0) -> الربع 1 | S9: =IF(D9<=12,"أطفال (0-12)",IF(D9<=24,"شباب (13-24)",IF(D9<=44,"بالغون (25-44)",IF(D9<=64,"متوسطو العمر (45-64)","كبار السن (+65)")))) -> متوسطو العمر (45-64) | T9: =IFERROR(L9/P9,0) -> 2326.35
A10: P11236 | B10: 45293 | C10: 45295 | D10: 15 | E10: ذكر | F10: الطوارئ | G10: ألم صدر حاد | H10: د. فهد المطيري | I10: طارئة | J10: خاصة | K10: ضمان اجتماعي | L10: 3402 | M10: 4 | N10: لا | O10: خرج بحالة مستقرة | P10: =C10-B10 -> 2 | Q10: =CHOOSE(MONTH(B10),"يناير","فبراير","مارس","أبريل","مايو","يونيو","يوليو","أغسطس","سبتمبر","أكتوبر","نوفمبر","ديسمبر") -> يناير | R10: ="الربع "&ROUNDUP(MONTH(B10)/3,0) -> الربع 1 | S10: =IF(D10<=12,"أطفال (0-12)",IF(D10<=24,"شباب (13-24)",IF(D10<=44,"بالغون (25-44)",IF(D10<=64,"متوسطو العمر (45-64)","كبار السن (+65)")))) -> شباب (13-24) | T10: =IFERROR(L10/P10,0) -> 1701
A11: P11293 | B11: 45293 | C11: 45305 | D11: 43 | E11: ذكر | F11: الأورام | G11: متابعة ورم | H11: د. فيصل الرشيدي | I11: تحويل من مستشفى آخر | J11: عناية مركزة | K11: تأمين خاص | L11: 136069.86 | M11: 4 | N11: لا | O11: خرج بحالة مستقرة | P11: =C11-B11 -> 12 | Q11: =CHOOSE(MONTH(B11),"يناير","فبراير","مارس","أبريل","مايو","يونيو","يوليو","أغسطس","سبتمبر","أكتوبر","نوفمبر","ديسمبر") -> يناير | R11: ="الربع "&ROUNDUP(MONTH(B11)/3,0) -> الربع 1 | S11: =IF(D11<=12,"أطفال (0-12)",IF(D11<=24,"شباب (13-24)",IF(D11<=44,"بالغون (25-44)",IF(D11<=64,"متوسطو العمر (45-64)","كبار السن (+65)")))) -> بالغون (25-44) | T11: =IFERROR(L11/P11,0) -> 11339.155
A12: P11549 | B12: 45293 | C12: 45294 | D12: 34 | E12: أنثى | F12: الطوارئ | G12: ألم صدر حاد | H12: د. سارة الحربي | I12: طارئة | J12: خاصة | K12: تأمين حكومي | L12: 1312.42 | M12: 4 | N12: لا | O12: خرج بحالة مستقرة | P12: =C12-B12 -> 1 | Q12: =CHOOSE(MONTH(B12),"يناير","فبراير","مارس","أبريل","مايو","يونيو","يوليو","أغسطس","سبتمبر","أكتوبر","نوفمبر","ديسمبر") -> يناير | R12: ="الربع "&ROUNDUP(MONTH(B12)/3,0) -> الربع 1 | S12: =IF(D12<=12,"أطفال (0-12)",IF(D12<=24,"شباب (13-24)",IF(D12<=44,"بالغون (25-44)",IF(D12<=64,"متوسطو العمر (45-64)","كبار السن (+65)")))) -> بالغون (25-44) | T12: =IFERROR(L12/P12,0) -> 1312.42
A13: P10900 | B13: 45293 | C13: 45295 | D13: 46 | E13: أنثى | F13: الطوارئ | G13: كسر طارئ | H13: د. نورة العتيبي | I13: طارئة | J13: عناية مركزة | K13: تأمين حكومي | L13: 5762.89 | M13: 3 | N13: لا | O13: خرج بحالة مستقرة | P13: =C13-B13 -> 2 | Q13: =CHOOSE(MONTH(B13),"يناير","فبراير","مارس","أبريل","مايو","يونيو","يوليو","أغسطس","سبتمبر","أكتوبر","نوفمبر","ديسمبر") -> يناير | R13: ="الربع "&ROUNDUP(MONTH(B13)/3,0) -> الربع 1 | S13: =IF(D13<=12,"أطفال (0-12)",IF(D13<=24,"شباب (13-24)",IF(D13<=44,"بالغون (25-44)",IF(D13<=64,"متوسطو العمر (45-64)","كبار السن (+65)")))) -> متوسطو العمر (45-64) | T13: =IFERROR(L13/P13,0) -> 2881.445
A14: P11738 | B14: 45293 | C14: 45294 | D14: 4 | E14: أنثى | F14: الأطفال | G14: جفاف حاد | H14: د. سلطان الجهني | I14: طارئة | J14: خاصة | K14: تأمين خاص | L14: 1867.3 | M14: 4 | N14: لا | O14: خرج بحالة مستقرة | P14: =C14-B14 -> 1 | Q14: =CHOOSE(MONTH(B14),"يناير","فبراير","مارس","أبريل","مايو","يونيو","يوليو","أغسطس","سبتمبر","أكتوبر","نوفمبر","ديسمبر") -> يناير | R14: ="الربع "&ROUNDUP(MONTH(B14)/3,0) -> الربع 1 | S14: =IF(D14<=12,"أطفال (0-12)",IF(D14<=24,"شباب (13-24)",IF(D14<=44,"بالغون (25-44)",IF(D14<=64,"متوسطو العمر (45-64)","كبار السن (+65)")))) -> أطفال (0-12) | T14: =IFERROR(L14/P14,0) -> 1867.3
... A2102: P11168 | B2102: 45657 | C2102: 45658 | D2102: 0 | E2102: أنثى | F2102: الطوارئ | G2102: إصابة حادة | H2102: د. نورة العتيبي | I2102: طارئة | J2102: خاصة | K2102: تأمين حكومي | L2102: 1537.28 | M2102: 5 | N2102: لا | O2102: خرج بحالة مستقرة | P2102: =C2102-B2102 -> 1 | Q2102: =CHOOSE(MONTH(B2102),"يناير","فبراير","مارس","أبريل","مايو","يونيو","يوليو","أغسطس","سبتمبر","أكتوبر","نوفمبر","ديسمبر") -> ديسمبر | R2102: ="الربع "&ROUNDUP(MONTH(B2102)/3,0) -> الربع 4 | S2102: =IF(D2102<=12,"أطفال (0-12)",IF(D2102<=24,"شباب (13-24)",IF(D2102<=44,"بالغون (25-44)",IF(D2102<=64,"متوسطو العمر (45-64)","كبار السن (+65)")))) -> أطفال (0-12) | T2102: =IFERROR(L2102/P2102,0) -> 1537.28

Sheet 06 الجداول التحليلية
A1: الجداول التحليلية الشاملة (بديل الجدول المحوري) — كل الأرقام محسوبة مباشرة من شيت البيانات النظيفة بصيغ SUMIFS/COUNTIFS/AVERAGEIFS
A3: 1) ملخص شامل حسب القسم الطبي
A4: القسم | B4: عدد المرضى | C4: إجمالي الإيرادات (ر.س) | D4: متوسط تكلفة الحالة | E4: متوسط مدة الإقامة (يوم) | F4: متوسط تقييم الرضا | G4: نسبة إعادة الدخول
A5: الطوارئ | B5: =COUNTIF('05 البيانات النظيفة'!$F$3:$F$2102,$A5) -> 468 | C5: =SUMIF('05 البيانات النظيفة'!$F$3:$F$2102,$A5,'05 البيانات النظيفة'!$L$3:$L$2102) -> 876630.23 | D5: =AVERAGEIF('05 البيانات النظيفة'!$F$3:$F$2102,$A5,'05 البيانات النظيفة'!$L$3:$L$2102) -> 1873.1415 | E5: =AVERAGEIF('05 البيانات النظيفة'!$F$3:$F$2102,$A5,'05 البيانات النظيفة'!$P$3:$P$2102) -> 1.4401709 | F5: =AVERAGEIF('05 البيانات النظيفة'!$F$3:$F$2102,$A5,'05 البيانات النظيفة'!$M$3:$M$2102) -> 3.3974359 | G5: =COUNTIFS('05 البيانات النظيفة'!$F$3:$F$2102,$A5,'05 البيانات النظيفة'!$N$3:$N$2102,"نعم")/COUNTIF('05 البيانات النظيفة'!$F$3:$F$2102,$A5) -> 0.072649573
A6: الباطنة | B6: =COUNTIF('05 البيانات النظيفة'!$F$3:$F$2102,$A6) -> 360 | C6: =SUMIF('05 البيانات النظيفة'!$F$3:$F$2102,$A6,'05 البيانات النظيفة'!$L$3:$L$2102) -> 2566400.5 | D6: =AVERAGEIF('05 البيانات النظيفة'!$F$3:$F$2102,$A6,'05 البيانات النظيفة'!$L$3:$L$2102) -> 7128.8904 | E6: =AVERAGEIF('05 البيانات النظيفة'!$F$3:$F$2102,$A6,'05 البيانات النظيفة'!$P$3:$P$2102) -> 4.5888889 | F6: =AVERAGEIF('05 البيانات النظيفة'!$F$3:$F$2102,$A6,'05 البيانات النظيفة'!$M$3:$M$2102) -> 4.0472222 | G6: =COUNTIFS('05 البيانات النظيفة'!$F$3:$F$2102,$A6,'05 البيانات النظيفة'!$N$3:$N$2102,"نعم")/COUNTIF('05 البيانات النظيفة'!$F$3:$F$2102,$A6) -> 0.086111111
A7: الجراحة العامة | B7: =COUNTIF('05 البيانات النظيفة'!$F$3:$F$2102,$A7) -> 218 | C7: =SUMIF('05 البيانات النظيفة'!$F$3:$F$2102,$A7,'05 البيانات النظيفة'!$L$3:$L$2102) -> 2793368.2 | D7: =AVERAGEIF('05 البيانات النظيفة'!$F$3:$F$2102,$A7,'05 البيانات النظيفة'!$L$3:$L$2102) -> 12813.615 | E7: =AVERAGEIF('05 البيانات النظيفة'!$F$3:$F$2102,$A7,'05 البيانات النظيفة'!$P$3:$P$2102) -> 4.1513761 | F7: =AVERAGEIF('05 البيانات النظيفة'!$F$3:$F$2102,$A7,'05 البيانات النظيفة'!$M$3:$M$2102) -> 4 | G7: =COUNTIFS('05 البيانات النظيفة'!$F$3:$F$2102,$A7,'05 البيانات النظيفة'!$N$3:$N$2102,"نعم")/COUNTIF('05 البيانات النظيفة'!$F$3:$F$2102,$A7) -> 0.091743119
A8: العظام | B8: =COUNTIF('05 البيانات النظيفة'!$F$3:$F$2102,$A8) -> 230 | C8: =SUMIF('05 البيانات النظيفة'!$F$3:$F$2102,$A8,'05 البيانات النظيفة'!$L$3:$L$2102) -> 3703190.2 | D8: =AVERAGEIF('05 البيانات النظيفة'!$F$3:$F$2102,$A8,'05 البيانات النظيفة'!$L$3:$L$2102) -> 16100.827 | E8: =AVERAGEIF('05 البيانات النظيفة'!$F$3:$F$2102,$A8,'05 البيانات النظيفة'!$P$3:$P$2102) -> 4.3434783 | F8: =AVERAGEIF('05 البيانات النظيفة'!$F$3:$F$2102,$A8,'05 البيانات النظيفة'!$M$3:$M$2102) -> 4.0608696 | G8: =COUNTIFS('05 البيانات النظيفة'!$F$3:$F$2102,$A8,'05 البيانات النظيفة'!$N$3:$N$2102,"نعم")/COUNTIF('05 البيانات النظيفة'!$F$3:$F$2102,$A8) -> 0.086956522
A9: أمراض القلب | B9: =COUNTIF('05 البيانات النظيفة'!$F$3:$F$2102,$A9) -> 200 | C9: =SUMIF('05 البيانات النظيفة'!$F$3:$F$2102,$A9,'05 البيانات النظيفة'!$L$3:$L$2102) -> 4209630.4 | D9: =AVERAGEIF('05 البيانات النظيفة'!$F$3:$F$2102,$A9,'05 البيانات النظيفة'!$L$3:$L$2102) -> 21048.152 | E9: =AVERAGEIF('05 البيانات النظيفة'!$F$3:$F$2102,$A9,'05 البيانات النظيفة'!$P$3:$P$2102) -> 5.69 | F9: =AVERAGEIF('05 البيانات النظيفة'!$F$3:$F$2102,$A9,'05 البيانات النظيفة'!$M$3:$M$2102) -> 3.98 | G9: =COUNTIFS('05 البيانات النظيفة'!$F$3:$F$2102,$A9,'05 البيانات النظيفة'!$N$3:$N$2102,"نعم")/COUNTIF('05 البيانات النظيفة'!$F$3:$F$2102,$A9) -> 0.185
A10: الأطفال | B10: =COUNTIF('05 البيانات النظيفة'!$F$3:$F$2102,$A10) -> 293 | C10: =SUMIF('05 البيانات النظيفة'!$F$3:$F$2102,$A10,'05 البيانات النظيفة'!$L$3:$L$2102) -> 922980.63 | D10: =AVERAGEIF('05 البيانات النظيفة'!$F$3:$F$2102,$A10,'05 البيانات النظيفة'!$L$3:$L$2102) -> 3150.1045 | E10: =AVERAGEIF('05 البيانات النظيفة'!$F$3:$F$2102,$A10,'05 البيانات النظيفة'!$P$3:$P$2102) -> 2.6279863 | F10: =AVERAGEIF('05 البيانات النظيفة'!$F$3:$F$2102,$A10,'05 البيانات النظيفة'!$M$3:$M$2102) -> 4.0784983 | G10: =COUNTIFS('05 البيانات النظيفة'!$F$3:$F$2102,$A10,'05 البيانات النظيفة'!$N$3:$N$2102,"نعم")/COUNTIF('05 البيانات النظيفة'!$F$3:$F$2102,$A10) -> 0.092150171
A11: النساء والولادة | B11: =COUNTIF('05 البيانات النظيفة'!$F$3:$F$2102,$A11) -> 202 | C11: =SUMIF('05 البيانات النظيفة'!$F$3:$F$2102,$A11,'05 البيانات النظيفة'!$L$3:$L$2102) -> 990780.35 | D11: =AVERAGEIF('05 البيانات النظيفة'!$F$3:$F$2102,$A11,'05 البيانات النظيفة'!$L$3:$L$2102) -> 4904.8532 | E11: =AVERAGEIF('05 البيانات النظيفة'!$F$3:$F$2102,$A11,'05 البيانات النظيفة'!$P$3:$P$2102) -> 2.2722772 | F11: =AVERAGEIF('05 البيانات النظيفة'!$F$3:$F$2102,$A11,'05 البيانات النظيفة'!$M$3:$M$2102) -> 3.990099 | G11: =COUNTIFS('05 البيانات النظيفة'!$F$3:$F$2102,$A11,'05 البيانات النظيفة'!$N$3:$N$2102,"نعم")/COUNTIF('05 البيانات النظيفة'!$F$3:$F$2102,$A11) -> 0.084158416
A12: الأورام | B12: =COUNTIF('05 البيانات النظيفة'!$F$3:$F$2102,$A12) -> 129 | C12: =SUMIF('05 البيانات النظيفة'!$F$3:$F$2102,$A12,'05 البيانات النظيفة'!$L$3:$L$2102) -> 4540495.8 | D12: =AVERAGEIF('05 البيانات النظيفة'!$F$3:$F$2102,$A12,'05 البيانات النظيفة'!$L$3:$L$2102) -> 35197.642 | E12: =AVERAGEIF('05 البيانات النظيفة'!$F$3:$F$2102,$A12,'05 البيانات النظيفة'!$P$3:$P$2102) -> 6.4263566 | F12: =AVERAGEIF('05 البيانات النظيفة'!$F$3:$F$2102,$A12,'05 البيانات النظيفة'!$M$3:$M$2102) -> 4 | G12: =COUNTIFS('05 البيانات النظيفة'!$F$3:$F$2102,$A12,'05 البيانات النظيفة'!$N$3:$N$2102,"نعم")/COUNTIF('05 البيانات النظيفة'!$F$3:$F$2102,$A12) -> 0.1627907
A13: الإجمالي / المعدل العام | B13: =SUM(B5:B12) -> 2100 | C13: =SUM(C5:C12) -> 20603476 | D13: =AVERAGE('05 البيانات النظيفة'!$L$3:$L$2102) -> 9811.1792 | E13: =AVERAGE('05 البيانات النظيفة'!$P$3:$P$2102) -> 3.5361905 | F13: =AVERAGE('05 البيانات النظيفة'!$M$3:$M$2102) -> 3.8885714 | G13: =COUNTIF('05 البيانات النظيفة'!$N$3:$N$2102,"نعم")/COUNT('05 البيانات النظيفة'!$D$3:$D$2102) -> 0.098571429
A15: 2) الاتجاه الشهري لعدد المرضى والإيرادات (2024)
A16: الشهر | B16: عدد المرضى | C16: إجمالي الإيرادات (ر.س) | D16: متوسط مدة الإقامة (يوم)
A17: يناير | B17: =COUNTIF('05 البيانات النظيفة'!$Q$3:$Q$2102,$A17) -> 164 | C17: =SUMIF('05 البيانات النظيفة'!$Q$3:$Q$2102,$A17,'05 البيانات النظيفة'!$L$3:$L$2102) -> 1448481.9 | D17: =AVERAGEIF('05 البيانات النظيفة'!$Q$3:$Q$2102,$A17,'05 البيانات النظيفة'!$P$3:$P$2102) -> 3.2195122
A18: فبراير | B18: =COUNTIF('05 البيانات النظيفة'!$Q$3:$Q$2102,$A18) -> 198 | C18: =SUMIF('05 البيانات النظيفة'!$Q$3:$Q$2102,$A18,'05 البيانات النظيفة'!$L$3:$L$2102) -> 2031699 | D18: =AVERAGEIF('05 البيانات النظيفة'!$Q$3:$Q$2102,$A18,'05 البيانات النظيفة'!$P$3:$P$2102) -> 3.5808081
A19: مارس | B19: =COUNTIF('05 البيانات النظيفة'!$Q$3:$Q$2102,$A19) -> 161 | C19: =SUMIF('05 البيانات النظيفة'!$Q$3:$Q$2102,$A19,'05 البيانات النظيفة'!$L$3:$L$2102) -> 1196977.3 | D19: =AVERAGEIF('05 البيانات النظيفة'!$Q$3:$Q$2102,$A19,'05 البيانات النظيفة'!$P$3:$P$2102) -> 3.1180124
A20: أبريل | B20: =COUNTIF('05 البيانات النظيفة'!$Q$3:$Q$2102,$A20) -> 172 | C20: =SUMIF('05 البيانات النظيفة'!$Q$3:$Q$2102,$A20,'05 البيانات النظيفة'!$L$3:$L$2102) -> 1946497.2 | D20: =AVERAGEIF('05 البيانات النظيفة'!$Q$3:$Q$2102,$A20,'05 البيانات النظيفة'!$P$3:$P$2102) -> 3.7906977
A21: مايو | B21: =COUNTIF('05 البيانات النظيفة'!$Q$3:$Q$2102,$A21) -> 160 | C21: =SUMIF('05 البيانات النظيفة'!$Q$3:$Q$2102,$A21,'05 البيانات النظيفة'!$L$3:$L$2102) -> 1353244.2 | D21: =AVERAGEIF('05 البيانات النظيفة'!$Q$3:$Q$2102,$A21,'05 البيانات النظيفة'!$P$3:$P$2102) -> 3.4125
A22: يونيو | B22: =COUNTIF('05 البيانات النظيفة'!$Q$3:$Q$2102,$A22) -> 187 | C22: =SUMIF('05 البيانات النظيفة'!$Q$3:$Q$2102,$A22,'05 البيانات النظيفة'!$L$3:$L$2102) -> 1406723.7 | D22: =AVERAGEIF('05 البيانات النظيفة'!$Q$3:$Q$2102,$A22,'05 البيانات النظيفة'!$P$3:$P$2102) -> 3.1336898
A23: يوليو | B23: =COUNTIF('05 البيانات النظيفة'!$Q$3:$Q$2102,$A23) -> 182 | C23: =SUMIF('05 البيانات النظيفة'!$Q$3:$Q$2102,$A23,'05 البيانات النظيفة'!$L$3:$L$2102) -> 1780136.7 | D23: =AVERAGEIF('05 البيانات النظيفة'!$Q$3:$Q$2102,$A23,'05 البيانات النظيفة'!$P$3:$P$2102) -> 3.7527473
A24: أغسطس | B24: =COUNTIF('05 البيانات النظيفة'!$Q$3:$Q$2102,$A24) -> 175 | C24: =SUMIF('05 البيانات النظيفة'!$Q$3:$Q$2102,$A24,'05 البيانات النظيفة'!$L$3:$L$2102) -> 1726157.9 | D24: =AVERAGEIF('05 البيانات النظيفة'!$Q$3:$Q$2102,$A24,'05 البيانات النظيفة'!$P$3:$P$2102) -> 3.2685714
A25: سبتمبر | B25: =COUNTIF('05 البيانات النظيفة'!$Q$3:$Q$2102,$A25) -> 170 | C25: =SUMIF('05 البيانات النظيفة'!$Q$3:$Q$2102,$A25,'05 البيانات النظيفة'!$L$3:$L$2102) -> 1761634.8 | D25: =AVERAGEIF('05 البيانات النظيفة'!$Q$3:$Q$2102,$A25,'05 البيانات النظيفة'!$P$3:$P$2102) -> 3.6176471
A26: أكتوبر | B26: =COUNTIF('05 البيانات النظيفة'!$Q$3:$Q$2102,$A26) -> 177 | C26: =SUMIF('05 البيانات النظيفة'!$Q$3:$Q$2102,$A26,'05 البيانات النظيفة'!$L$3:$L$2102) -> 1971538.3 | D26: =AVERAGEIF('05 البيانات النظيفة'!$Q$3:$Q$2102,$A26,'05 البيانات النظيفة'!$P$3:$P$2102) -> 3.5367232
A27: نوفمبر | B27: =COUNTIF('05 البيانات النظيفة'!$Q$3:$Q$2102,$A27) -> 167 | C27: =SUMIF('05 البيانات النظيفة'!$Q$3:$Q$2102,$A27,'05 البيانات النظيفة'!$L$3:$L$2102) -> 1815377.8 | D27: =AVERAGEIF('05 البيانات النظيفة'!$Q$3:$Q$2102,$A27,'05 البيانات النظيفة'!$P$3:$P$2102) -> 3.994012
A28: ديسمبر | B28: =COUNTIF('05 البيانات النظيفة'!$Q$3:$Q$2102,$A28) -> 187 | C28: =SUMIF('05 البيانات النظيفة'!$Q$3:$Q$2102,$A28,'05 البيانات النظيفة'!$L$3:$L$2102) -> 2165007.3 | D28: =AVERAGEIF('05 البيانات النظيفة'!$Q$3:$Q$2102,$A28,'05 البيانات النظيفة'!$P$3:$P$2102) -> 3.9572193
A31: 3) التوزيع حسب نوع التأمين
A32: نوع التأمين | B32: عدد المرضى | C32: النسبة من الإجمالي | D32: متوسط تكلفة الحالة | E32: متوسط تقييم الرضا
A33: تأمين حكومي | B33: =COUNTIF('05 البيانات النظيفة'!$K$3:$K$2102,$A33) -> 922 | C33: =B33/COUNT('05 البيانات النظيفة'!$D$3:$D$2102) -> 0.43904762 | D33: =AVERAGEIF('05 البيانات النظيفة'!$K$3:$K$2102,$A33,'05 البيانات النظيفة'!$L$3:$L$2102) -> 10047.23 | E33: =AVERAGEIF('05 البيانات النظيفة'!$K$3:$K$2102,$A33,'05 البيانات النظيفة'!$M$3:$M$2102) -> 3.9240781
A34: تأمين خاص | B34: =COUNTIF('05 البيانات النظيفة'!$K$3:$K$2102,$A34) -> 578 | C34: =B34/COUNT('05 البيانات النظيفة'!$D$3:$D$2102) -> 0.2752381 | D34: =AVERAGEIF('05 البيانات النظيفة'!$K$3:$K$2102,$A34,'05 البيانات النظيفة'!$L$3:$L$2102) -> 9668.7365 | E34: =AVERAGEIF('05 البيانات النظيفة'!$K$3:$K$2102,$A34,'05 البيانات النظيفة'!$M$3:$M$2102) -> 3.9152249
A35: ضمان اجتماعي | B35: =COUNTIF('05 البيانات النظيفة'!$K$3:$K$2102,$A35) -> 387 | C35: =B35/COUNT('05 البيانات النظيفة'!$D$3:$D$2102) -> 0.18428571 | D35: =AVERAGEIF('05 البيانات النظيفة'!$K$3:$K$2102,$A35,'05 البيانات النظيفة'!$L$3:$L$2102) -> 9362.2411 | E35: =AVERAGEIF('05 البيانات النظيفة'!$K$3:$K$2102,$A35,'05 البيانات النظيفة'!$M$3:$M$2102) -> 3.9328165
A36: بدون تأمين (ذاتي) | B36: =COUNTIF('05 البيانات النظيفة'!$K$3:$K$2102,$A36) -> 213 | C36: =B36/COUNT('05 البيانات النظيفة'!$D$3:$D$2102) -> 0.10142857 | D36: =AVERAGEIF('05 البيانات النظيفة'!$K$3:$K$2102,$A36,'05 البيانات النظيفة'!$L$3:$L$2102) -> 9991.6111 | E36: =AVERAGEIF('05 البيانات النظيفة'!$K$3:$K$2102,$A36,'05 البيانات النظيفة'!$M$3:$M$2102) -> 3.5821596
A39: 4) التوزيع حسب الفئة العمرية
A40: الفئة العمرية | B40: عدد المرضى | C40: متوسط تكلفة الحالة | D40: متوسط مدة الإقامة (يوم)
A41: أطفال (0-12) | B41: =COUNTIF('05 البيانات النظيفة'!$S$3:$S$2102,$A41) -> 358 | C41: =AVERAGEIF('05 البيانات النظيفة'!$S$3:$S$2102,$A41,'05 البيانات النظيفة'!$L$3:$L$2102) -> 4153.5836 | D41: =AVERAGEIF('05 البيانات النظيفة'!$S$3:$S$2102,$A41,'05 البيانات النظيفة'!$P$3:$P$2102) -> 2.7178771
A42: شباب (13-24) | B42: =COUNTIF('05 البيانات النظيفة'!$S$3:$S$2102,$A42) -> 202 | C42: =AVERAGEIF('05 البيانات النظيفة'!$S$3:$S$2102,$A42,'05 البيانات النظيفة'!$L$3:$L$2102) -> 6886.1901 | D42: =AVERAGEIF('05 البيانات النظيفة'!$S$3:$S$2102,$A42,'05 البيانات النظيفة'!$P$3:$P$2102) -> 3.0693069
A43: بالغون (25-44) | B43: =COUNTIF('05 البيانات النظيفة'!$S$3:$S$2102,$A43) -> 614 | C43: =AVERAGEIF('05 البيانات النظيفة'!$S$3:$S$2102,$A43,'05 البيانات النظيفة'!$L$3:$L$2102) -> 8658.8453 | D43: =AVERAGEIF('05 البيانات النظيفة'!$S$3:$S$2102,$A43,'05 البيانات النظيفة'!$P$3:$P$2102) -> 3.3355049
A44: متوسطو العمر (45-64) | B44: =COUNTIF('05 البيانات النظيفة'!$S$3:$S$2102,$A44) -> 601 | C44: =AVERAGEIF('05 البيانات النظيفة'!$S$3:$S$2102,$A44,'05 البيانات النظيفة'!$L$3:$L$2102) -> 13350.659 | D44: =AVERAGEIF('05 البيانات النظيفة'!$S$3:$S$2102,$A44,'05 البيانات النظيفة'!$P$3:$P$2102) -> 4.0216306
A45: كبار السن (+65) | B45: =COUNTIF('05 البيانات النظيفة'!$S$3:$S$2102,$A45) -> 325 | C45: =AVERAGEIF('05 البيانات النظيفة'!$S$3:$S$2102,$A45,'05 البيانات النظيفة'!$L$3:$L$2102) -> 13492.941 | D45: =AVERAGEIF('05 البيانات النظيفة'!$S$3:$S$2102,$A45,'05 البيانات النظيفة'!$P$3:$P$2102) -> 4.2092308
A48: 5) التوزيع حسب نوع الغرفة
...

Sheet 07 لوحة التحكم
B1: لوحة تحكم عمليات المستشفى — المؤشرات الرئيسية لعام 2024
B4: 👥 | D4: 💰 | F4: 🛏️ | H4: ⭐ | J4: ↩️
B5: ='06 الجداول التحليلية'!B13 -> 2100 | D5: ='06 الجداول التحليلية'!C13 -> 20603476 | F5: ='06 الجداول التحليلية'!E13 -> 3.5361905 | H5: ='06 الجداول التحليلية'!F13 -> 3.8885714 | J5: ='06 الجداول التحليلية'!G13 -> 0.098571429
B6: إجمالي عدد المرضى | D6: إجمالي الإيرادات (ر.س) | F6: متوسط مدة الإقامة (يوم) | H6: متوسط تقييم رضا المريض | J6: نسبة إعادة الدخول خلال 30 يوم
B9: 🧾 | D9: ⚕️ | F9: 🏥 | H9: 📈 | J9: 🛌
B10: ='06 الجداول التحليلية'!D13 -> 9811.1792 | D10: ='06 الجداول التحليلية'!C67 -> 0.013809524 | F10: =INDEX('06 الجداول التحليلية'!$A$5:$A$12,MATCH(MAX('06 الجداول التحليلية'!$C$5:$C$12),'06 الجداول التحليلية'!$C$5:$C$12,0)) -> الأورام | H10: =INDEX('06 الجداول التحليلية'!$A$17:$A$28,MATCH(MAX('06 الجداول التحليلية'!$B$17:$B$28),'06 الجداول التحليلية'!$B$17:$B$28,0)) -> فبراير | J10: =INDEX('06 الجداول التحليلية'!$A$5:$A$12,MATCH(MAX('06 الجداول التحليلية'!$E$5:$E$12),'06 الجداول التحليلية'!$E$5:$E$12,0)) -> الأورام
B11: متوسط تكلفة الحالة (ر.س) | D11: نسبة الوفيات | F11: القسم الأعلى إيراداً | H11: أكثر الأشهر ازدحاماً | J11: أعلى قسم بمدة الإقامة
B14: 🔍 فلتر تفاعلي — اختر قسماً لعرض أداءه التفصيلي فوراً
B15: القسم المختار: | C15: الطوارئ | F15: عدد المرضى | G15: إجمالي الإيرادات | H15: متوسط تكلفة الحالة | I15: متوسط مدة الإقامة | J15: متوسط الرضا | K15: نسبة إعادة الدخول
F16: =INDEX('06 الجداول التحليلية'!$B$5:$B$12,MATCH($C$15,'06 الجداول التحليلية'!$A$5:$A$12,0)) -> 468 | G16: =INDEX('06 الجداول التحليلية'!$C$5:$C$12,MATCH($C$15,'06 الجداول التحليلية'!$A$5:$A$12,0)) -> 876630.23 | H16: =INDEX('06 الجداول التحليلية'!$D$5:$D$12,MATCH($C$15,'06 الجداول التحليلية'!$A$5:$A$12,0)) -> 1873.1415 | I16: =INDEX('06 الجداول التحليلية'!$E$5:$E$12,MATCH($C$15,'06 الجداول التحليلية'!$A$5:$A$12,0)) -> 1.4401709 | J16: =INDEX('06 الجداول التحليلية'!$F$5:$F$12,MATCH($C$15,'06 الجداول التحليلية'!$A$5:$A$12,0)) -> 3.3974359 | K16: =INDEX('06 الجداول التحليلية'!$G$5:$G$12,MATCH($C$15,'06 الجداول التحليلية'!$A$5:$A$12,0)) -> 0.072649573

Sheet 08 رسوم بيانية إضافية
B1: رسوم بيانية تحليلية تكميلية

Sheet 09 الرؤى والتوصيات
A1: الرؤى الرئيسية والتوصيات الاستراتيجية
A2: مبنية بالكامل على الأرقام الفعلية المحسوبة في شيتي «الجداول التحليلية» و«لوحة التحكم»
A4: 📋 ملخص تنفيذي
A5: استقبل المستشفى 2,100 حالة دخول خلال عام 2024 بإجمالي إيرادات بلغ نحو 20.6 مليون ريال بمتوسط تكلفة 9,811 ريال للحالة، ومتوسط مدة إقامة 3.54 يوم، ومتوسط رضا 3.89 من 5. أبرز التحديات: نسبة إعادة دخول عامة 9.9% ترتفع بشكل حاد في أمراض القلب (18.5%) والأورام (16.3%)، ورضا منخفض نسبياً في الطوارئ (3.40) رغم أنها الأعلى حجماً (22% من الحالات)، إضافة إلى تفاوت كبير في الربحية بين الأقسام يستدعي مراجعة التسعير والتحويلات الداخلية.
A7: 💰 الإيرادات مركّزة في أقسام قليلة عالية التكلفة
A8: قسم الأورام يحقق أعلى إيراد إجمالي (4.54 مليون ريال) رغم كونه الأصغر من حيث عدد المرضى (129 حالة فقط، 6% من الإجمالي)، بمتوسط تكلفة حالة يبلغ 35,198 ريال — الأعلى بين جميع الأقسام. في المقابل، تستحوذ الطوارئ على 22% من إجمالي المرضى لكنها تساهم بأقل من 4.3% فقط من الإيرادات (876 ألف ريال)، بمتوسط تكلفة حالة لا يتجاوز 1,873 ريال.
A9: ✅ التوصية: إعادة تقييم نموذج التسعير في الطوارئ (رسوم فرز/تقييم أولي)، مع تعزيز الطاقة الاستيعابية لأقسام الأورام والقلب والجراحة العامة نظراً لعائدها المرتفع على كل حالة.
A11: 🛏️ غرف العناية المركزة: 12% من المرضى لكن تكلفة يوم أعلى بـ3.6 ضعف
A12: غرف العناية المركزة تخدم 247 مريضاً فقط (11.8% من الإجمالي) لكنها تولّد 6.4 مليون ريال من الإيرادات بمتوسط تكلفة يوم 5,724 ريال، مقارنة بـ1,572 ريال فقط للغرف العادية (فارق 3.6 ضعف) و2,922 ريال للغرف الخاصة. هذا يجعل كفاءة استخدام أسرّة العناية المركزة عاملاً حاسماً في الربحية التشغيلية.
A13: ✅ التوصية: تطبيق نظام حجز ومتابعة يومي لإشغال العناية المركزة، وربط معايير القبول فيها بدرجة الخطورة السريرية لتقليل الإقامات غير الضرورية وزيادة معدل الدوران.
A15: ↩️ أمراض القلب والأورام: أعلى نسب إعادة الدخول خلال 30 يوماً
A16: تسجل أمراض القلب أعلى نسبة إعادة دخول بين كل الأقسام (18.5%)، تليها الأورام (16.3%) — أي ضعف المعدل العام تقريباً (9.9%). هذا النمط يتكرر أيضاً على مستوى الأطباء: أعلى نسبة إعادة دخول فردية لطبيبة الأورام (24.6%)، تليها طبيبان في أمراض القلب (18.7% و17.9%)، وكلها أعلى من المتوسط العام بوضوح.
... A40: ملاحظة منهجية: جميع الأرقام أعلاه محسوبة مباشرة بصيغ حية من شيت «06 الجداول التحليلية»، وتتحدث تلقائياً عند تعديل البيانات في شيت «05 البيانات النظيفة».
